
If the anaconda3/personal module is the only one you're using in your jobscripts, then you should consider moving to our newer cluster - CX3 Phase 2.
It provides a number of improvements as well as new GPU's (NVIDIA L40S's). It runs off of the RDS, meaning all your work will remain as is.
All you need to do is log in to the new cluster:
https://icl-rcs-user-guide.readthedocs.io/en/latest/hpc/pilot/cx3-phase2/
https://icl-rcs-user-guide.readthedocs.io/en/latest/hpc/pilot/cx3-phase2/#python-and-conda-environments

As always, if you have any questions, please raise a ticket with us here:
https://www.imperial.ac.uk/admin-services/ict/self-service/research-support/rcs/get-support/contact-us/

No permission to create OpenML directory at /rds/general/user/nz423/home/.config/openml! This can result in OpenML-Python not working properly.
Traceback (most recent call last):
  File "/rds/general/user/nz423/home/anaconda3/envs/pytorch_env/lib/python3.11/site-packages/openml/datasets/functions.py", line 1173, in _get_dataset_description
    with description_file.open(encoding="utf8") as fh:
         ^^^^^^^^^^^^^^^^^^^^^^^^^^^^^^^^^^^^^^
  File "/rds/general/user/nz423/home/anaconda3/envs/pytorch_env/lib/python3.11/pathlib.py", line 1044, in open
    return io.open(self, mode, buffering, encoding, errors, newline)
           ^^^^^^^^^^^^^^^^^^^^^^^^^^^^^^^^^^^^^^^^^^^^^^^^^^^^^^^^^
FileNotFoundError: [Errno 2] No such file or directory: '/rds/general/user/nz423/home/.cache/openml/org/openml/www/datasets/44957/description.xml'

During handling of the above exception, another exception occurred:

Traceback (most recent call last):
  File "/rds/general/user/nz423/home/random-feature-boosting/scripts/../regression_param_specs.py", line 336, in <module>
    run_all_openML_with_model(
  File "/rds/general/user/nz423/home/random-feature-boosting/optuna_kfoldCV.py", line 355, in run_all_openML_with_model
    X, y = pytorch_load_openml_dataset(dataset_id, regression_or_classification)
           ^^^^^^^^^^^^^^^^^^^^^^^^^^^^^^^^^^^^^^^^^^^^^^^^^^^^^^^^^^^^^^^^^^^^^
  File "/rds/general/user/nz423/home/random-feature-boosting/optuna_kfoldCV.py", line 83, in pytorch_load_openml_dataset
    X, y = np_load_openml_dataset(dataset_id, regression_or_classification)
           ^^^^^^^^^^^^^^^^^^^^^^^^^^^^^^^^^^^^^^^^^^^^^^^^^^^^^^^^^^^^^^^^
  File "/rds/general/user/nz423/home/random-feature-boosting/optuna_kfoldCV.py", line 51, in np_load_openml_dataset
    dataset = openml.datasets.get_dataset(dataset_id)
              ^^^^^^^^^^^^^^^^^^^^^^^^^^^^^^^^^^^^^^^
  File "/rds/general/user/nz423/home/anaconda3/envs/pytorch_env/lib/python3.11/site-packages/openml/datasets/functions.py", line 593, in get_dataset
    raise e
  File "/rds/general/user/nz423/home/anaconda3/envs/pytorch_env/lib/python3.11/site-packages/openml/datasets/functions.py", line 561, in get_dataset
    description = _get_dataset_description(did_cache_dir, dataset_id)
                  ^^^^^^^^^^^^^^^^^^^^^^^^^^^^^^^^^^^^^^^^^^^^^^^^^^^
  File "/rds/general/user/nz423/home/anaconda3/envs/pytorch_env/lib/python3.11/site-packages/openml/datasets/functions.py", line 1178, in _get_dataset_description
    dataset_xml = openml._api_calls._perform_api_call(url_extension, "get")
                  ^^^^^^^^^^^^^^^^^^^^^^^^^^^^^^^^^^^^^^^^^^^^^^^^^^^^^^^^^
  File "/rds/general/user/nz423/home/anaconda3/envs/pytorch_env/lib/python3.11/site-packages/openml/_api_calls.py", line 117, in _perform_api_call
    response = __read_url(url, request_method, data)
               ^^^^^^^^^^^^^^^^^^^^^^^^^^^^^^^^^^^^^
  File "/rds/general/user/nz423/home/anaconda3/envs/pytorch_env/lib/python3.11/site-packages/openml/_api_calls.py", line 337, in __read_url
    return _send_request(
           ^^^^^^^^^^^^^^
  File "/rds/general/user/nz423/home/anaconda3/envs/pytorch_env/lib/python3.11/site-packages/openml/_api_calls.py", line 436, in _send_request
    raise retry_raise_e
  File "/rds/general/user/nz423/home/anaconda3/envs/pytorch_env/lib/python3.11/site-packages/openml/_api_calls.py", line 382, in _send_request
    __check_response(response=response, url=url, file_elements=files)
  File "/rds/general/user/nz423/home/anaconda3/envs/pytorch_env/lib/python3.11/site-packages/openml/_api_calls.py", line 450, in __check_response
    raise __parse_server_exception(response, url, file_elements=file_elements)
openml.exceptions.OpenMLServerException: https://www.openml.org/api/v1/xml/data/44957 returned code 107: Database connection error. Usually due to high server load. Please wait for N seconds and try again. - None
